<mujoco>
  <compiler angle="degree" coordinate="local" inertiafromgeom="true" />
  <option integrator="RK4" timestep="0.8" />
  <default>
    <joint armature="0" damping="0" limited="false" />
    <geom conaffinity="0" condim="3" density="100" friction="1 0.5 0.5" margin="0.01" rgba="0.8 0.6 0.4 1" />
  </default>
  <asset>
    <texture builtin="gradient" height="100" rgb1="1 1 1" rgb2="0 0 0" type="skybox" width="100" />
    <texture builtin="flat" height="1278" mark="cross" markrgb="1 1 1" name="texgeom" random="0.01" rgb1="0.8 0.6 0.4" rgb2="0.8 0.6 0.4" type="cube" width="127" />


    <material name="geom" texture="texgeom" texuniform="true" />
  </asset>
  <worldbody>
    <light cutoff="100" diffuse="1 1 1" dir="0 0 -1" directional="false" exponent="1" pos="3 3 1.3" specular=".1 .1 .1" />
    <geom conaffinity="1" condim="3" material="" name="floor" pos="0 0 0" rgba="0.4 0.4 0.4 1" size="40 40 40" type="plane" />
    <body name="torso" pos="0 0 0">
      <camera fovy="15" mode="fixed" name="track" pos="-0.5 0 0.6" xyaxes="0 -1 0 0 0 1" />
      <geom name="pointbody" pos="0 0 0.5" size="0.5" type="sphere" />
      <geom name="pointarrow" pos="0.5 0 0.5" size="0.5 0.1 0.1" type="box" />
      <joint axis="1 0 0" damping="40" name="ballx" pos="0 0 0" type="slide" />
      <joint axis="0 1 0" damping="40" name="bally" pos="0 0 0" type="slide" />
      <joint axis="0 0 1" damping="40" limited="false" name="rot" pos="0 0 0" type="hinge" />
    </body>
    <geom conaffinity="1" contype="1" material="" name="block_0_0" pos="-3.0 -3.0 1.5" rgba="0.59 0.31 0.02 1" size="1.5 1.5 1.5" type="box" /><geom conaffinity="1" contype="1" material="" name="block_0_1" pos="0.0 -3.0 1.5" rgba="0.59 0.31 0.02 1" size="1.5 1.5 1.5" type="box" /><geom conaffinity="1" contype="1" material="" name="block_0_2" pos="3.0 -3.0 1.5" rgba="0.59 0.31 0.02 1" size="1.5 1.5 1.5" type="box" /><geom conaffinity="1" contype="1" material="" name="block_0_3" pos="6.0 -3.0 1.5" rgba="0.59 0.31 0.02 1" size="1.5 1.5 1.5" type="box" /><geom conaffinity="1" contype="1" material="" name="block_0_4" pos="9.0 -3.0 1.5" rgba="0.59 0.31 0.02 1" size="1.5 1.5 1.5" type="box" /><geom conaffinity="1" contype="1" material="" name="block_0_5" pos="12.0 -3.0 1.5" rgba="0.59 0.31 0.02 1" size="1.5 1.5 1.5" type="box" /><geom conaffinity="1" contype="1" material="" name="block_0_6" pos="15.0 -3.0 1.5" rgba="0.59 0.31 0.02 1" size="1.5 1.5 1.5" type="box" /><geom conaffinity="1" contype="1" material="" name="block_0_7" pos="18.0 -3.0 1.5" rgba="0.59 0.31 0.02 1" size="1.5 1.5 1.5" type="box" /><geom conaffinity="1" contype="1" material="" name="block_0_8" pos="21.0 -3.0 1.5" rgba="0.59 0.31 0.02 1" size="1.5 1.5 1.5" type="box" /><geom conaffinity="1" contype="1" material="" name="block_1_0" pos="-3.0 0.0 1.5" rgba="0.59 0.31 0.02 1" size="1.5 1.5 1.5" type="box" /><geom conaffinity="1" contype="1" material="" name="block_1_6" pos="15.0 0.0 1.5" rgba="0.59 0.31 0.02 1" size="1.5 1.5 1.5" type="box" /><geom conaffinity="1" contype="1" material="" name="block_1_8" pos="21.0 0.0 1.5" rgba="0.59 0.31 0.02 1" size="1.5 1.5 1.5" type="box" /><geom conaffinity="1" contype="1" material="" name="block_2_0" pos="-3.0 3.0 1.5" rgba="0.59 0.31 0.02 1" size="1.5 1.5 1.5" type="box" /><geom conaffinity="1" contype="1" material="" name="block_2_1" pos="0.0 3.0 1.5" rgba="0.59 0.31 0.02 1" size="1.5 1.5 1.5" type="box" /><geom conaffinity="1" contype="1" material="" name="block_2_2" pos="3.0 3.0 1.5" rgba="0.59 0.31 0.02 1" size="1.5 1.5 1.5" type="box" /><geom conaffinity="1" contype="1" material="" name="block_2_3" pos="6.0 3.0 1.5" rgba="0.59 0.31 0.02 1" size="1.5 1.5 1.5" type="box" /><geom conaffinity="1" contype="1" material="" name="block_2_4" pos="9.0 3.0 1.5" rgba="0.59 0.31 0.02 1" size="1.5 1.5 1.5" type="box" /><geom conaffinity="1" contype="1" material="" name="block_2_6" pos="15.0 3.0 1.5" rgba="0.59 0.31 0.02 1" size="1.5 1.5 1.5" type="box" /><geom conaffinity="1" contype="1" material="" name="block_2_8" pos="21.0 3.0 1.5" rgba="0.59 0.31 0.02 1" size="1.5 1.5 1.5" type="box" /><geom conaffinity="1" contype="1" material="" name="block_3_0" pos="-3.0 6.0 1.5" rgba="0.59 0.31 0.02 1" size="1.5 1.5 1.5" type="box" /><geom conaffinity="1" contype="1" material="" name="block_3_4" pos="9.0 6.0 1.5" rgba="0.59 0.31 0.02 1" size="1.5 1.5 1.5" type="box" /><geom conaffinity="1" contype="1" material="" name="block_3_6" pos="15.0 6.0 1.5" rgba="0.59 0.31 0.02 1" size="1.5 1.5 1.5" type="box" /><geom conaffinity="1" contype="1" material="" name="block_3_8" pos="21.0 6.0 1.5" rgba="0.59 0.31 0.02 1" size="1.5 1.5 1.5" type="box" /><geom conaffinity="1" contype="1" material="" name="block_4_0" pos="-3.0 9.0 1.5" rgba="0.59 0.31 0.02 1" size="1.5 1.5 1.5" type="box" /><geom conaffinity="1" contype="1" material="" name="block_4_2" pos="3.0 9.0 1.5" rgba="0.59 0.31 0.02 1" size="1.5 1.5 1.5" type="box" /><geom conaffinity="1" contype="1" material="" name="block_4_4" pos="9.0 9.0 1.5" rgba="0.59 0.31 0.02 1" size="1.5 1.5 1.5" type="box" /><geom conaffinity="1" contype="1" material="" name="block_4_6" pos="15.0 9.0 1.5" rgba="0.59 0.31 0.02 1" size="1.5 1.5 1.5" type="box" /><geom conaffinity="1" contype="1" material="" name="block_4_8" pos="21.0 9.0 1.5" rgba="0.59 0.31 0.02 1" size="1.5 1.5 1.5" type="box" /><geom conaffinity="1" contype="1" material="" name="block_5_0" pos="-3.0 12.0 1.5" rgba="0.59 0.31 0.02 1" size="1.5 1.5 1.5" type="box" /><geom conaffinity="1" contype="1" material="" name="block_5_2" pos="3.0 12.0 1.5" rgba="0.59 0.31 0.02 1" size="1.5 1.5 1.5" type="box" /><geom conaffinity="1" contype="1" material="" name="block_5_6" pos="15.0 12.0 1.5" rgba="0.59 0.31 0.02 1" size="1.5 1.5 1.5" type="box" /><geom conaffinity="1" contype="1" material="" name="block_5_8" pos="21.0 12.0 1.5" rgba="0.59 0.31 0.02 1" size="1.5 1.5 1.5" type="box" /><geom conaffinity="1" contype="1" material="" name="block_6_0" pos="-3.0 15.0 1.5" rgba="0.59 0.31 0.02 1" size="1.5 1.5 1.5" type="box" /><geom conaffinity="1" contype="1" material="" name="block_6_2" pos="3.0 15.0 1.5" rgba="0.59 0.31 0.02 1" size="1.5 1.5 1.5" type="box" /><geom conaffinity="1" contype="1" material="" name="block_6_3" pos="6.0 15.0 1.5" rgba="0.59 0.31 0.02 1" size="1.5 1.5 1.5" type="box" /><geom conaffinity="1" contype="1" material="" name="block_6_4" pos="9.0 15.0 1.5" rgba="0.59 0.31 0.02 1" size="1.5 1.5 1.5" type="box" /><geom conaffinity="1" contype="1" material="" name="block_6_5" pos="12.0 15.0 1.5" rgba="0.59 0.31 0.02 1" size="1.5 1.5 1.5" type="box" /><geom conaffinity="1" contype="1" material="" name="block_6_6" pos="15.0 15.0 1.5" rgba="0.59 0.31 0.02 1" size="1.5 1.5 1.5" type="box" /><geom conaffinity="1" contype="1" material="" name="block_6_8" pos="21.0 15.0 1.5" rgba="0.59 0.31 0.02 1" size="1.5 1.5 1.5" type="box" /><geom conaffinity="1" contype="1" material="" name="block_7_0" pos="-3.0 18.0 1.5" rgba="0.59 0.31 0.02 1" size="1.5 1.5 1.5" type="box" /><geom conaffinity="1" contype="1" material="" name="block_7_8" pos="21.0 18.0 1.5" rgba="0.59 0.31 0.02 1" size="1.5 1.5 1.5" type="box" /><geom conaffinity="1" contype="1" material="" name="block_8_0" pos="-3.0 21.0 1.5" rgba="0.59 0.31 0.02 1" size="1.5 1.5 1.5" type="box" /><geom conaffinity="1" contype="1" material="" name="block_8_1" pos="0.0 21.0 1.5" rgba="0.59 0.31 0.02 1" size="1.5 1.5 1.5" type="box" /><geom conaffinity="1" contype="1" material="" name="block_8_2" pos="3.0 21.0 1.5" rgba="0.59 0.31 0.02 1" size="1.5 1.5 1.5" type="box" /><geom conaffinity="1" contype="1" material="" name="block_8_3" pos="6.0 21.0 1.5" rgba="0.59 0.31 0.02 1" size="1.5 1.5 1.5" type="box" /><geom conaffinity="1" contype="1" material="" name="block_8_4" pos="9.0 21.0 1.5" rgba="0.59 0.31 0.02 1" size="1.5 1.5 1.5" type="box" /><geom conaffinity="1" contype="1" material="" name="block_8_5" pos="12.0 21.0 1.5" rgba="0.59 0.31 0.02 1" size="1.5 1.5 1.5" type="box" /><geom conaffinity="1" contype="1" material="" name="block_8_6" pos="15.0 21.0 1.5" rgba="0.59 0.31 0.02 1" size="1.5 1.5 1.5" type="box" /><geom conaffinity="1" contype="1" material="" name="block_8_7" pos="18.0 21.0 1.5" rgba="0.59 0.31 0.02 1" size="1.5 1.5 1.5" type="box" /><geom conaffinity="1" contype="1" material="" name="block_8_8" pos="21.0 21.0 1.5" rgba="0.59 0.31 0.02 1" size="1.5 1.5 1.5" type="box" />
    <camera mode="fixed" name="world" pos="9.0000 9.0000 29.1962" xyaxes="1 0 0 0.0000 1.0000 0.0000" />
  </worldbody>
  <actuator>
    <position joint="ballx" kp="75" />
    <position joint="bally" kp="75" />
    <position joint="rot" kp="75" />
  </actuator>
</mujoco>
